Workbook

Sheet 1 
E1: =Total!F5 -> 69 | F1: =Total!G5 -> العبور
B3: م | C3: IPN | D3: إسم العميل | E3: رقم التليفون | F3: قيمة الشحنه | G3: قيمة الرسوم / العموله | H3: الاجمــــــــــالي | I3: نوع الخدمة | J3: التاريخ | L3: التاريخ | M3: 1.5.2026 | O3: مبيعــــــــــــــــــــــــــات الكارت | P3: =M5+M6 -> 0
B4: 1 | G4: =IF(Basic34567891011121314151617181920212223242526272829303132[[#This Row],[نوع الخدمة]]="مخالفات", 50, IF(Basic34567891011121314151617181920212223242526272829303132[[#This Row],[نوع الخدمة]]="كاش ان", IF(F4<=100, 18, IF(F4<=250, 23, IF(F4<=500, 35, IF(F4<=1000, 40, F4*0.04)))), IF(Basic34567891011121314151617181920212223242526272829303132[[#This Row],[نوع الخدمة]]="كاش اوت", IF(F4<=100, 15, IF(F4<=250, 20, IF(F4<=500, 30, IF(F4<=1000, 35, F4*0.035)))), 0))) -> 0 | H4: =IF(I4="مخالفات",50,Basic34567891011121314151617181920212223242526272829303132[[#This Row],[قيمة الرسوم / العموله]]+Basic34567891011121314151617181920212223242526272829303132[[#This Row],[قيمة الشحنه]]) -> 0 | J4: =M$3 -> 1.5.2026 | L4: العهده | O4: رصيد العــــــــــــــــــــــــــــــهده اول اليوم | P4: =M4 -> 0 | S4: اجمالي الشحنات | T4: اجمالي الكروت
B5: 2 | G5: =IF(Basic34567891011121314151617181920212223242526272829303132[[#This Row],[نوع الخدمة]]="مخالفات", 50, IF(Basic34567891011121314151617181920212223242526272829303132[[#This Row],[نوع الخدمة]]="كاش ان", IF(F5<=100, 18, IF(F5<=250, 23, IF(F5<=500, 35, IF(F5<=1000, 40, F5*0.04)))), IF(Basic34567891011121314151617181920212223242526272829303132[[#This Row],[نوع الخدمة]]="كاش اوت", IF(F5<=100, 15, IF(F5<=250, 20, IF(F5<=500, 30, IF(F5<=1000, 35, F5*0.035)))), 0))) -> 0 | H5: =IF(I5="مخالفات",50,Basic34567891011121314151617181920212223242526272829303132[[#This Row],[قيمة الرسوم / العموله]]+Basic34567891011121314151617181920212223242526272829303132[[#This Row],[قيمة الشحنه]]) -> 0 | J5: =M$3 -> 1.5.2026 | L5: كارت مصر | O5: مبلغ الشحن (العهده) | P5: =SUMIF(Basic34567891011121314151617181920212223242526272829303132[نوع الخدمة],"كاش ان",Basic34567891011121314151617181920212223242526272829303132[قيمة الشحنه]) -> 0 | S5: =P5+P9+P12+P7 -> 0 | T5: =P3 -> 0
B6: 3 | G6: =IF(Basic34567891011121314151617181920212223242526272829303132[[#This Row],[نوع الخدمة]]="مخالفات", 50, IF(Basic34567891011121314151617181920212223242526272829303132[[#This Row],[نوع الخدمة]]="كاش ان", IF(F6<=100, 18, IF(F6<=250, 23, IF(F6<=500, 35, IF(F6<=1000, 40, F6*0.04)))), IF(Basic34567891011121314151617181920212223242526272829303132[[#This Row],[نوع الخدمة]]="كاش اوت", IF(F6<=100, 15, IF(F6<=250, 20, IF(F6<=500, 30, IF(F6<=1000, 35, F6*0.035)))), 0))) -> 0 | H6: =IF(I6="مخالفات",50,Basic34567891011121314151617181920212223242526272829303132[[#This Row],[قيمة الرسوم / العموله]]+Basic34567891011121314151617181920212223242526272829303132[[#This Row],[قيمة الشحنه]]) -> 0 | J6: =M$3 -> 1.5.2026 | L6: كارت اهلي | O6: مبلغ الكروت اليومى | P6: =P3*150 -> 0
B7: 4 | G7: =IF(Basic34567891011121314151617181920212223242526272829303132[[#This Row],[نوع الخدمة]]="مخالفات", 50, IF(Basic34567891011121314151617181920212223242526272829303132[[#This Row],[نوع الخدمة]]="كاش ان", IF(F7<=100, 18, IF(F7<=250, 23, IF(F7<=500, 35, IF(F7<=1000, 40, F7*0.04)))), IF(Basic34567891011121314151617181920212223242526272829303132[[#This Row],[نوع الخدمة]]="كاش اوت", IF(F7<=100, 15, IF(F7<=250, 20, IF(F7<=500, 30, IF(F7<=1000, 35, F7*0.035)))), 0))) -> 0 | H7: =IF(I7="مخالفات",50,Basic34567891011121314151617181920212223242526272829303132[[#This Row],[قيمة الرسوم / العموله]]+Basic34567891011121314151617181920212223242526272829303132[[#This Row],[قيمة الشحنه]]) -> 0 | J7: =M$3 -> 1.5.2026 | L7: المردودات | M7: 0 | O7: مبلغ المخالفات اليومي | P7: =SUMIF(Basic34567891011121314151617181920212223242526272829303132[نوع الخدمة],"مخالفات",Basic34567891011121314151617181920212223242526272829303132[الاجمــــــــــالي]) -> 0
B8: 5 | G8: =IF(Basic34567891011121314151617181920212223242526272829303132[[#This Row],[نوع الخدمة]]="مخالفات", 50, IF(Basic34567891011121314151617181920212223242526272829303132[[#This Row],[نوع الخدمة]]="كاش ان", IF(F8<=100, 18, IF(F8<=250, 23, IF(F8<=500, 35, IF(F8<=1000, 40, F8*0.04)))), IF(Basic34567891011121314151617181920212223242526272829303132[[#This Row],[نوع الخدمة]]="كاش اوت", IF(F8<=100, 15, IF(F8<=250, 20, IF(F8<=500, 30, IF(F8<=1000, 35, F8*0.035)))), 0))) -> 0 | H8: =IF(I8="مخالفات",50,Basic34567891011121314151617181920212223242526272829303132[[#This Row],[قيمة الرسوم / العموله]]+Basic34567891011121314151617181920212223242526272829303132[[#This Row],[قيمة الشحنه]]) -> 0 | J8: =M$3 -> 1.5.2026 | L8: وارد مصر | O8: المردودات | P8: =M7 -> 0 | R8: الدايلي تـــــــــــــــــــــــــارجت | S8: تحقيق اليوم | T8: % | U8: الدايلي كروت | V8: تحقيق اليوم | W8: % | BH8: كاش ان
B9: 6 | G9: =IF(Basic34567891011121314151617181920212223242526272829303132[[#This Row],[نوع الخدمة]]="مخالفات", 50, IF(Basic34567891011121314151617181920212223242526272829303132[[#This Row],[نوع الخدمة]]="كاش ان", IF(F9<=100, 18, IF(F9<=250, 23, IF(F9<=500, 35, IF(F9<=1000, 40, F9*0.04)))), IF(Basic34567891011121314151617181920212223242526272829303132[[#This Row],[نوع الخدمة]]="كاش اوت", IF(F9<=100, 15, IF(F9<=250, 20, IF(F9<=500, 30, IF(F9<=1000, 35, F9*0.035)))), 0))) -> 0 | H9: =IF(I9="مخالفات",50,Basic34567891011121314151617181920212223242526272829303132[[#This Row],[قيمة الرسوم / العموله]]+Basic34567891011121314151617181920212223242526272829303132[[#This Row],[قيمة الشحنه]]) -> 0 | J9: =M$3 -> 1.5.2026 | L9: وارد اهلى | O9: مبلغ الرسوم | P9: =SUMIF(Basic34567891011121314151617181920212223242526272829303132[نوع الخدمة],"كاش ان",Basic34567891011121314151617181920212223242526272829303132[قيمة الرسوم / العموله]) -> 0 | R9: =Total!H5/24 -> 29166.667 | S9: =S5 -> 0 | T9: =S9/R9 -> 0 | U9: =Total!K5/24 -> 2.9166667 | V9: =T5 -> 0 | W9: =V9/U9 -> 0 | BH9: كاش اوت
B10: 7 | G10: =IF(Basic34567891011121314151617181920212223242526272829303132[[#This Row],[نوع الخدمة]]="مخالفات", 50, IF(Basic34567891011121314151617181920212223242526272829303132[[#This Row],[نوع الخدمة]]="كاش ان", IF(F10<=100, 18, IF(F10<=250, 23, IF(F10<=500, 35, IF(F10<=1000, 40, F10*0.04)))), IF(Basic34567891011121314151617181920212223242526272829303132[[#This Row],[نوع الخدمة]]="كاش اوت", IF(F10<=100, 15, IF(F10<=250, 20, IF(F10<=500, 30, IF(F10<=1000, 35, F10*0.035)))), 0))) -> 0 | H10: =IF(I10="مخالفات",50,Basic34567891011121314151617181920212223242526272829303132[[#This Row],[قيمة الرسوم / العموله]]+Basic34567891011121314151617181920212223242526272829303132[[#This Row],[قيمة الشحنه]]) -> 0 | J10: =M$3 -> 1.5.2026 | O10: اجمالي كاش اوت(بدون الرسوم) | P10: =SUMIF(Basic34567891011121314151617181920212223242526272829303132[نوع الخدمة],"كاش اوت",Basic34567891011121314151617181920212223242526272829303132[قيمة الشحنه]) -> 0 | R10: =(W9+T9)/2 -> 0 | BH10: مخالفات
B11: 8 | G11: =IF(Basic34567891011121314151617181920212223242526272829303132[[#This Row],[نوع الخدمة]]="مخالفات", 50, IF(Basic34567891011121314151617181920212223242526272829303132[[#This Row],[نوع الخدمة]]="كاش ان", IF(F11<=100, 18, IF(F11<=250, 23, IF(F11<=500, 35, IF(F11<=1000, 40, F11*0.04)))), IF(Basic34567891011121314151617181920212223242526272829303132[[#This Row],[نوع الخدمة]]="كاش اوت", IF(F11<=100, 15, IF(F11<=250, 20, IF(F11<=500, 30, IF(F11<=1000, 35, F11*0.035)))), 0))) -> 0 | H11: =IF(I11="مخالفات",50,Basic34567891011121314151617181920212223242526272829303132[[#This Row],[قيمة الرسوم / العموله]]+Basic34567891011121314151617181920212223242526272829303132[[#This Row],[قيمة الشحنه]]) -> 0 | J11: =M$3 -> 1.5.2026 | L11: # | M11: التوكن | O11: التوريـــــــــــــــــــــــــــــــــــــــــد النقدي( الدرج) | P11: =(P5+P6+P9+P7+P4)-P10-P8 -> 0
B12: 9 | G12: =IF(Basic34567891011121314151617181920212223242526272829303132[[#This Row],[نوع الخدمة]]="مخالفات", 50, IF(Basic34567891011121314151617181920212223242526272829303132[[#This Row],[نوع الخدمة]]="كاش ان", IF(F12<=100, 18, IF(F12<=250, 23, IF(F12<=500, 35, IF(F12<=1000, 40, F12*0.04)))), IF(Basic34567891011121314151617181920212223242526272829303132[[#This Row],[نوع الخدمة]]="كاش اوت", IF(F12<=100, 15, IF(F12<=250, 20, IF(F12<=500, 30, IF(F12<=1000, 35, F12*0.035)))), 0))) -> 0 | H12: =IF(I12="مخالفات",50,Basic34567891011121314151617181920212223242526272829303132[[#This Row],[قيمة الرسوم / العموله]]+Basic34567891011121314151617181920212223242526272829303132[[#This Row],[قيمة الشحنه]]) -> 0 | J12: =M$3 -> 1.5.2026 | L12: 1 | O12: اجمالي كاش اوت( بالرسوم) | P12: =SUMIF(Basic34567891011121314151617181920212223242526272829303132[نوع الخدمة],"كاش اوت",Basic34567891011121314151617181920212223242526272829303132[الاجمــــــــــالي]) -> 0
B13: 10 | G13: =IF(Basic34567891011121314151617181920212223242526272829303132[[#This Row],[نوع الخدمة]]="مخالفات", 50, IF(Basic34567891011121314151617181920212223242526272829303132[[#This Row],[نوع الخدمة]]="كاش ان", IF(F13<=100, 18, IF(F13<=250, 23, IF(F13<=500, 35, IF(F13<=1000, 40, F13*0.04)))), IF(Basic34567891011121314151617181920212223242526272829303132[[#This Row],[نوع الخدمة]]="كاش اوت", IF(F13<=100, 15, IF(F13<=250, 20, IF(F13<=500, 30, IF(F13<=1000, 35, F13*0.035)))), 0))) -> 0 | H13: =IF(I13="مخالفات",50,Basic34567891011121314151617181920212223242526272829303132[[#This Row],[قيمة الرسوم / العموله]]+Basic34567891011121314151617181920212223242526272829303132[[#This Row],[قيمة الشحنه]]) -> 0 | J13: =M$3 -> 1.5.2026 | L13: 2
B14: 11 | G14: =IF(Basic34567891011121314151617181920212223242526272829303132[[#This Row],[نوع الخدمة]]="مخالفات", 50, IF(Basic34567891011121314151617181920212223242526272829303132[[#This Row],[نوع الخدمة]]="كاش ان", IF(F14<=100, 18, IF(F14<=250, 23, IF(F14<=500, 35, IF(F14<=1000, 40, F14*0.04)))), IF(Basic34567891011121314151617181920212223242526272829303132[[#This Row],[نوع الخدمة]]="كاش اوت", IF(F14<=100, 15, IF(F14<=250, 20, IF(F14<=500, 30, IF(F14<=1000, 35, F14*0.035)))), 0))) -> 0 | H14: =IF(I14="مخالفات",50,Basic34567891011121314151617181920212223242526272829303132[[#This Row],[قيمة الرسوم / العموله]]+Basic34567891011121314151617181920212223242526272829303132[[#This Row],[قيمة الشحنه]]) -> 0 | J14: =M$3 -> 1.5.2026 | L14: 3 | O14: مخالفات | P14: =COUNTIF(Basic34567891011121314151617181920212223242526272829303132[نوع الخدمة],"مخالفات") -> 0
B15: 12 | G15: =IF(Basic34567891011121314151617181920212223242526272829303132[[#This Row],[نوع الخدمة]]="مخالفات", 50, IF(Basic34567891011121314151617181920212223242526272829303132[[#This Row],[نوع الخدمة]]="كاش ان", IF(F15<=100, 18, IF(F15<=250, 23, IF(F15<=500, 35, IF(F15<=1000, 40, F15*0.04)))), IF(Basic34567891011121314151617181920212223242526272829303132[[#This Row],[نوع الخدمة]]="كاش اوت", IF(F15<=100, 15, IF(F15<=250, 20, IF(F15<=500, 30, IF(F15<=1000, 35, F15*0.035)))), 0))) -> 0 | H15: =IF(I15="مخالفات",50,Basic34567891011121314151617181920212223242526272829303132[[#This Row],[قيمة الرسوم / العموله]]+Basic34567891011121314151617181920212223242526272829303132[[#This Row],[قيمة الشحنه]]) -> 0 | J15: =M$3 -> 1.5.2026 | L15: 4 | O15: عدد الحركات Cash In | P15: =COUNTIF(Basic34567891011121314151617181920212223242526272829303132[نوع الخدمة],"كاش ان") -> 0
B16: 13 | G16: =IF(Basic34567891011121314151617181920212223242526272829303132[[#This Row],[نوع الخدمة]]="مخالفات", 50, IF(Basic34567891011121314151617181920212223242526272829303132[[#This Row],[نوع الخدمة]]="كاش ان", IF(F16<=100, 18, IF(F16<=250, 23, IF(F16<=500, 35, IF(F16<=1000, 40, F16*0.04)))), IF(Basic34567891011121314151617181920212223242526272829303132[[#This Row],[نوع الخدمة]]="كاش اوت", IF(F16<=100, 15, IF(F16<=250, 20, IF(F16<=500, 30, IF(F16<=1000, 35, F16*0.035)))), 0))) -> 0 | H16: =IF(I16="مخالفات",50,Basic34567891011121314151617181920212223242526272829303132[[#This Row],[قيمة الرسوم / العموله]]+Basic34567891011121314151617181920212223242526272829303132[[#This Row],[قيمة الشحنه]]) -> 0 | J16: =M$3 -> 1.5.2026 | L16: 5 | O16: عدد الحركات Cash Out | P16: =COUNTIF(Basic34567891011121314151617181920212223242526272829303132[نوع الخدمة],"كاش اوت") -> 0
B17: 14 | G17: =IF(Basic34567891011121314151617181920212223242526272829303132[[#This Row],[نوع الخدمة]]="مخالفات", 50, IF(Basic34567891011121314151617181920212223242526272829303132[[#This Row],[نوع الخدمة]]="كاش ان", IF(F17<=100, 18, IF(F17<=250, 23, IF(F17<=500, 35, IF(F17<=1000, 40, F17*0.04)))), IF(Basic34567891011121314151617181920212223242526272829303132[[#This Row],[نوع الخدمة]]="كاش اوت", IF(F17<=100, 15, IF(F17<=250, 20, IF(F17<=500, 30, IF(F17<=1000, 35, F17*0.035)))), 0))) -> 0 | H17: =IF(I17="مخالفات",50,Basic34567891011121314151617181920212223242526272829303132[[#This Row],[قيمة الرسوم / العموله]]+Basic34567891011121314151617181920212223242526272829303132[[#This Row],[قيمة الشحنه]]) -> 0 | J17: =M$3 -> 1.5.2026 | L17: 6 | O17: اجمالى عدد الحركات | P17: =P15+P16 -> 0
B18: 15 | G18: =IF(Basic34567891011121314151617181920212223242526272829303132[[#This Row],[نوع الخدمة]]="مخالفات", 50, IF(Basic34567891011121314151617181920212223242526272829303132[[#This Row],[نوع الخدمة]]="كاش ان", IF(F18<=100, 18, IF(F18<=250, 23, IF(F18<=500, 35, IF(F18<=1000, 40, F18*0.04)))), IF(Basic34567891011121314151617181920212223242526272829303132[[#This Row],[نوع الخدمة]]="كاش اوت", IF(F18<=100, 15, IF(F18<=250, 20, IF(F18<=500, 30, IF(F18<=1000, 35, F18*0.035)))), 0))) -> 0 | H18: =IF(I18="مخالفات",50,Basic34567891011121314151617181920212223242526272829303132[[#This Row],[قيمة الرسوم / العموله]]+Basic34567891011121314151617181920212223242526272829303132[[#This Row],[قيمة الشحنه]]) -> 0 | J18: =M$3 -> 1.5.2026 | L18: 7
B19: 16 | G19: =IF(Basic34567891011121314151617181920212223242526272829303132[[#This Row],[نوع الخدمة]]="مخالفات", 50, IF(Basic34567891011121314151617181920212223242526272829303132[[#This Row],[نوع الخدمة]]="كاش ان", IF(F19<=100, 18, IF(F19<=250, 23, IF(F19<=500, 35, IF(F19<=1000, 40, F19*0.04)))), IF(Basic34567891011121314151617181920212223242526272829303132[[#This Row],[نوع الخدمة]]="كاش اوت", IF(F19<=100, 15, IF(F19<=250, 20, IF(F19<=500, 30, IF(F19<=1000, 35, F19*0.035)))), 0))) -> 0 | H19: =IF(I19="مخالفات",50,Basic34567891011121314151617181920212223242526272829303132[[#This Row],[قيمة الرسوم / العموله]]+Basic34567891011121314151617181920212223242526272829303132[[#This Row],[قيمة الشحنه]]) -> 0 | J19: =M$3 -> 1.5.2026 | L19: 8 | O19: الجــــــــــــرد الفعلي للكروت
B20: 17 | G20: =IF(Basic34567891011121314151617181920212223242526272829303132[[#This Row],[نوع الخدمة]]="مخالفات", 50, IF(Basic34567891011121314151617181920212223242526272829303132[[#This Row],[نوع الخدمة]]="كاش ان", IF(F20<=100, 18, IF(F20<=250, 23, IF(F20<=500, 35, IF(F20<=1000, 40, F20*0.04)))), IF(Basic34567891011121314151617181920212223242526272829303132[[#This Row],[نوع الخدمة]]="كاش اوت", IF(F20<=100, 15, IF(F20<=250, 20, IF(F20<=500, 30, IF(F20<=1000, 35, F20*0.035)))), 0))) -> 0 | H20: =IF(I20="مخالفات",50,Basic34567891011121314151617181920212223242526272829303132[[#This Row],[قيمة الرسوم / العموله]]+Basic34567891011121314151617181920212223242526272829303132[[#This Row],[قيمة الشحنه]]) -> 0 | J20: =M$3 -> 1.5.2026 | L20: 9 | O20: المخـــــــــــــــــــــــــــــــــــــــــزون
B21: 18 | G21: =IF(Basic34567891011121314151617181920212223242526272829303132[[#This Row],[نوع الخدمة]]="مخالفات", 50, IF(Basic34567891011121314151617181920212223242526272829303132[[#This Row],[نوع الخدمة]]="كاش ان", IF(F21<=100, 18, IF(F21<=250, 23, IF(F21<=500, 35, IF(F21<=1000, 40, F21*0.04)))), IF(Basic34567891011121314151617181920212223242526272829303132[[#This Row],[نوع الخدمة]]="كاش اوت", IF(F21<=100, 15, IF(F21<=250, 20, IF(F21<=500, 30, IF(F21<=1000, 35, F21*0.035)))), 0))) -> 0 | H21: =IF(I21="مخالفات",50,Basic34567891011121314151617181920212223242526272829303132[[#This Row],[قيمة الرسوم / العموله]]+Basic34567891011121314151617181920212223242526272829303132[[#This Row],[قيمة الشحنه]]) -> 0 | J21: =M$3 -> 1.5.2026 | L21: 10 | O21: كارت مصر | P21: =M8 -> 0
B22: 19 | G22: =IF(Basic34567891011121314151617181920212223242526272829303132[[#This Row],[نوع الخدمة]]="مخالفات", 50, IF(Basic34567891011121314151617181920212223242526272829303132[[#This Row],[نوع الخدمة]]="كاش ان", IF(F22<=100, 18, IF(F22<=250, 23, IF(F22<=500, 35, IF(F22<=1000, 40, F22*0.04)))), IF(Basic34567891011121314151617181920212223242526272829303132[[#This Row],[نوع الخدمة]]="كاش اوت", IF(F22<=100, 15, IF(F22<=250, 20, IF(F22<=500, 30, IF(F22<=1000, 35, F22*0.035)))), 0))) -> 0 | H22: =IF(I22="مخالفات",50,Basic34567891011121314151617181920212223242526272829303132[[#This Row],[قيمة الرسوم / العموله]]+Basic34567891011121314151617181920212223242526272829303132[[#This Row],[قيمة الشحنه]]) -> 0 | J22: =M$3 -> 1.5.2026 | L22: 11 | O22: كارت اهلي | P22: =M9 -> 0
B23: 20 | G23: =IF(Basic34567891011121314151617181920212223242526272829303132[[#This Row],[نوع الخدمة]]="مخالفات", 50, IF(Basic34567891011121314151617181920212223242526272829303132[[#This Row],[نوع الخدمة]]="كاش ان", IF(F23<=100, 18, IF(F23<=250, 23, IF(F23<=500, 35, IF(F23<=1000, 40, F23*0.04)))), IF(Basic34567891011121314151617181920212223242526272829303132[[#This Row],[نوع الخدمة]]="كاش اوت", IF(F23<=100, 15, IF(F23<=250, 20, IF(F23<=500, 30, IF(F23<=1000, 35, F23*0.035)))), 0))) -> 0 | H23: =IF(I23="مخالفات",50,Basic34567891011121314151617181920212223242526272829303132[[#This Row],[قيمة الرسوم / العموله]]+Basic34567891011121314151617181920212223242526272829303132[[#This Row],[قيمة الشحنه]]) -> 0 | J23: =M$3 -> 1.5.2026 | L23: 12 | O23: المبيــــــــــــــــــــــــــــــــــــــــــــــــعات
B24: 21 | G24: =IF(Basic34567891011121314151617181920212223242526272829303132[[#This Row],[نوع الخدمة]]="مخالفات", 50, IF(Basic34567891011121314151617181920212223242526272829303132[[#This Row],[نوع الخدمة]]="كاش ان", IF(F24<=100, 18, IF(F24<=250, 23, IF(F24<=500, 35, IF(F24<=1000, 40, F24*0.04)))), IF(Basic34567891011121314151617181920212223242526272829303132[[#This Row],[نوع الخدمة]]="كاش اوت", IF(F24<=100, 15, IF(F24<=250, 20, IF(F24<=500, 30, IF(F24<=1000, 35, F24*0.035)))), 0))) -> 0 | H24: =IF(I24="مخالفات",50,Basic34567891011121314151617181920212223242526272829303132[[#This Row],[قيمة الرسوم / العموله]]+Basic34567891011121314151617181920212223242526272829303132[[#This Row],[قيمة الشحنه]]) -> 0 | J24: =M$3 -> 1.5.2026 | L24: 13 | O24: كارت مصر | P24: =M5 -> 0
B25: 22 | G25: =IF(Basic34567891011121314151617181920212223242526272829303132[[#This Row],[نوع الخدمة]]="مخالفات", 50, IF(Basic34567891011121314151617181920212223242526272829303132[[#This Row],[نوع الخدمة]]="كاش ان", IF(F25<=100, 18, IF(F25<=250, 23, IF(F25<=500, 35, IF(F25<=1000, 40, F25*0.04)))), IF(Basic34567891011121314151617181920212223242526272829303132[[#This Row],[نوع الخدمة]]="كاش اوت", IF(F25<=100, 15, IF(F25<=250, 20, IF(F25<=500, 30, IF(F25<=1000, 35, F25*0.035)))), 0))) -> 0 | H25: =IF(I25="مخالفات",50,Basic34567891011121314151617181920212223242526272829303132[[#This Row],[قيمة الرسوم / العموله]]+Basic34567891011121314151617181920212223242526272829303132[[#This Row],[قيمة الشحنه]]) -> 0 | J25: =M$3 -> 1.5.2026 | L25: 14 | O25: كارت اهلي | P25: =M6 -> 0
B26: 23 | G26: =IF(Basic34567891011121314151617181920212223242526272829303132[[#This Row],[نوع الخدمة]]="مخالفات", 50, IF(Basic34567891011121314151617181920212223242526272829303132[[#This Row],[نوع الخدمة]]="كاش ان", IF(F26<=100, 18, IF(F26<=250, 23, IF(F26<=500, 35, IF(F26<=1000, 40, F26*0.04)))), IF(Basic34567891011121314151617181920212223242526272829303132[[#This Row],[نوع الخدمة]]="كاش اوت", IF(F26<=100, 15, IF(F26<=250, 20, IF(F26<=500, 30, IF(F26<=1000, 35, F26*0.035)))), 0))) -> 0 | H26: =IF(I26="مخالفات",50,Basic34567891011121314151617181920212223242526272829303132[[#This Row],[قيمة الرسوم / العموله]]+Basic34567891011121314151617181920212223242526272829303132[[#This Row],[قيمة الشحنه]]) -> 0 | J26: =M$3 -> 1.5.2026 | L26: 15 | O26: المتبــــــــــــــــــــــــــــــــــــــــــــــــــــــقي
B27: 24 | G27: =IF(Basic34567891011121314151617181920212223242526272829303132[[#This Row],[نوع الخدمة]]="مخالفات", 50, IF(Basic34567891011121314151617181920212223242526272829303132[[#This Row],[نوع الخدمة]]="كاش ان", IF(F27<=100, 18, IF(F27<=250, 23, IF(F27<=500, 35, IF(F27<=1000, 40, F27*0.04)))), IF(Basic34567891011121314151617181920212223242526272829303132[[#This Row],[نوع الخدمة]]="كاش اوت", IF(F27<=100, 15, IF(F27<=250, 20, IF(F27<=500, 30, IF(F27<=1000, 35, F27*0.035)))), 0))) -> 0 | H27: =IF(I27="مخالفات",50,Basic34567891011121314151617181920212223242526272829303132[[#This Row],[قيمة الرسوم / العموله]]+Basic34567891011121314151617181920212223242526272829303132[[#This Row],[قيمة الشحنه]]) -> 0 | J27: =M$3 -> 1.5.2026 | L27: 16 | O27: كارت مصر | P27: =P21-P24 -> 0
B28: 25 | G28: =IF(Basic34567891011121314151617181920212223242526272829303132[[#This Row],[نوع الخدمة]]="مخالفات", 50, IF(Basic34567891011121314151617181920212223242526272829303132[[#This Row],[نوع الخدمة]]="كاش ان", IF(F28<=100, 18, IF(F28<=250, 23, IF(F28<=500, 35, IF(F28<=1000, 40, F28*0.04)))), IF(Basic34567891011121314151617181920212223242526272829303132[[#This Row],[نوع الخدمة]]="كاش اوت", IF(F28<=100, 15, IF(F28<=250, 20, IF(F28<=500, 30, IF(F28<=1000, 35, F28*0.035)))), 0))) -> 0 | H28: =IF(I28="مخالفات",50,Basic34567891011121314151617181920212223242526272829303132[[#This Row],[قيمة الرسوم / العموله]]+Basic34567891011121314151617181920212223242526272829303132[[#This Row],[قيمة الشحنه]]) -> 0 | J28: =M$3 -> 1.5.2026 | L28: 17 | O28: كارت اهلي | P28: =P22-P25 -> 0
B29: 26 | G29: =IF(Basic34567891011121314151617181920212223242526272829303132[[#This Row],[نوع الخدمة]]="مخالفات", 50, IF(Basic34567891011121314151617181920212223242526272829303132[[#This Row],[نوع الخدمة]]="كاش ان", IF(F29<=100, 18, IF(F29<=250, 23, IF(F29<=500, 35, IF(F29<=1000, 40, F29*0.04)))), IF(Basic34567891011121314151617181920212223242526272829303132[[#This Row],[نوع الخدمة]]="كاش اوت", IF(F29<=100, 15, IF(F29<=250, 20, IF(F29<=500, 30, IF(F29<=1000, 35, F29*0.035)))), 0))) -> 0 | H29: =IF(I29="مخالفات",50,Basic34567891011121314151617181920212223242526272829303132[[#This Row],[قيمة الرسوم / العموله]]+Basic34567891011121314151617181920212223242526272829303132[[#This Row],[قيمة الشحنه]]) -> 0 | J29: =M$3 -> 1.5.2026 | L29: 18
B30: 27 | G30: =IF(Basic34567891011121314151617181920212223242526272829303132[[#This Row],[نوع الخدمة]]="مخالفات", 50, IF(Basic34567891011121314151617181920212223242526272829303132[[#This Row],[نوع الخدمة]]="كاش ان", IF(F30<=100, 18, IF(F30<=250, 23, IF(F30<=500, 35, IF(F30<=1000, 40, F30*0.04)))), IF(Basic34567891011121314151617181920212223242526272829303132[[#This Row],[نوع الخدمة]]="كاش اوت", IF(F30<=100, 15, IF(F30<=250, 20, IF(F30<=500, 30, IF(F30<=1000, 35, F30*0.035)))), 0))) -> 0 | H30: =IF(I30="مخالفات",50,Basic34567891011121314151617181920212223242526272829303132[[#This Row],[قيمة الرسوم / العموله]]+Basic34567891011121314151617181920212223242526272829303132[[#This Row],[قيمة الشحنه]]) -> 0 | J30: =M$3 -> 1.5.2026 | L30: 19
B31: 28 | G31: =IF(Basic34567891011121314151617181920212223242526272829303132[[#This Row],[نوع الخدمة]]="مخالفات", 50, IF(Basic34567891011121314151617181920212223242526272829303132[[#This Row],[نوع الخدمة]]="كاش ان", IF(F31<=100, 18, IF(F31<=250, 23, IF(F31<=500, 35, IF(F31<=1000, 40, F31*0.04)))), IF(Basic34567891011121314151617181920212223242526272829303132[[#This Row],[نوع الخدمة]]="كاش اوت", IF(F31<=100, 15, IF(F31<=250, 20, IF(F31<=500, 30, IF(F31<=1000, 35, F31*0.035)))), 0))) -> 0 | H31: =IF(I31="مخالفات",50,Basic34567891011121314151617181920212223242526272829303132[[#This Row],[قيمة الرسوم / العموله]]+Basic34567891011121314151617181920212223242526272829303132[[#This Row],[قيمة الشحنه]]) -> 0 | J31: =M$3 -> 1.5.2026 | L31: 20
B32: 29 | G32: =IF(Basic34567891011121314151617181920212223242526272829303132[[#This Row],[نوع الخدمة]]="مخالفات", 50, IF(Basic34567891011121314151617181920212223242526272829303132[[#This Row],[نوع الخدمة]]="كاش ان", IF(F32<=100, 18, IF(F32<=250, 23, IF(F32<=500, 35, IF(F32<=1000, 40, F32*0.04)))), IF(Basic34567891011121314151617181920212223242526272829303132[[#This Row],[نوع الخدمة]]="كاش اوت", IF(F32<=100, 15, IF(F32<=250, 20, IF(F32<=500, 30, IF(F32<=1000, 35, F32*0.035)))), 0))) -> 0 | H32: =IF(I32="مخالفات",50,Basic34567891011121314151617181920212223242526272829303132[[#This Row],[قيمة الرسوم / العموله]]+Basic34567891011121314151617181920212223242526272829303132[[#This Row],[قيمة الشحنه]]) -> 0 | J32: =M$3 -> 1.5.2026 | L32: 21
B33: 30 | G33: =IF(Basic34567891011121314151617181920212223242526272829303132[[#This Row],[نوع الخدمة]]="مخالفات", 50, IF(Basic34567891011121314151617181920212223242526272829303132[[#This Row],[نوع الخدمة]]="كاش ان", IF(F33<=100, 18, IF(F33<=250, 23, IF(F33<=500, 35, IF(F33<=1000, 40, F33*0.04)))), IF(Basic34567891011121314151617181920212223242526272829303132[[#This Row],[نوع الخدمة]]="كاش اوت", IF(F33<=100, 15, IF(F33<=250, 20, IF(F33<=500, 30, IF(F33<=1000, 35, F33*0.035)))), 0))) -> 0 | H33: =IF(I33="مخالفات",50,Basic34567891011121314151617181920212223242526272829303132[[#This Row],[قيمة الرسوم / العموله]]+Basic34567891011121314151617181920212223242526272829303132[[#This Row],[قيمة الشحنه]]) -> 0 | J33: =M$3 -> 1.5.2026 | L33: 22
B34: 31 | G34: =IF(Basic34567891011121314151617181920212223242526272829303132[[#This Row],[نوع الخدمة]]="مخالفات", 50, IF(Basic34567891011121314151617181920212223242526272829303132[[#This Row],[نوع الخدمة]]="كاش ان", IF(F34<=100, 18, IF(F34<=250, 23, IF(F34<=500, 35, IF(F34<=1000, 40, F34*0.04)))), IF(Basic34567891011121314151617181920212223242526272829303132[[#This Row],[نوع الخدمة]]="كاش اوت", IF(F34<=100, 15, IF(F34<=250, 20, IF(F34<=500, 30, IF(F34<=1000, 35, F34*0.035)))), 0))) -> 0 | H34: =IF(I34="مخالفات",50,Basic34567891011121314151617181920212223242526272829303132[[#This Row],[قيمة الرسوم / العموله]]+Basic34567891011121314151617181920212223242526272829303132[[#This Row],[قيمة الشحنه]]) -> 0 | J34: =M$3 -> 1.5.2026 | L34: 23
B35: 32 | G35: =IF(Basic34567891011121314151617181920212223242526272829303132[[#This Row],[نوع الخدمة]]="مخالفات", 50, IF(Basic34567891011121314151617181920212223242526272829303132[[#This Row],[نوع الخدمة]]="كاش ان", IF(F35<=100, 18, IF(F35<=250, 23, IF(F35<=500, 35, IF(F35<=1000, 40, F35*0.04)))), IF(Basic34567891011121314151617181920212223242526272829303132[[#This Row],[نوع الخدمة]]="كاش اوت", IF(F35<=100, 15, IF(F35<=250, 20, IF(F35<=500, 30, IF(F35<=1000, 35, F35*0.035)))), 0))) -> 0 | H35: =IF(I35="مخالفات",50,Basic34567891011121314151617181920212223242526272829303132[[#This Row],[قيمة الرسوم / العموله]]+Basic34567891011121314151617181920212223242526272829303132[[#This Row],[قيمة الشحنه]]) -> 0 | J35: =M$3 -> 1.5.2026 | L35: 24
B36: 33 | G36: =IF(Basic34567891011121314151617181920212223242526272829303132[[#This Row],[نوع الخدمة]]="مخالفات", 50, IF(Basic34567891011121314151617181920212223242526272829303132[[#This Row],[نوع الخدمة]]="كاش ان", IF(F36<=100, 18, IF(F36<=250, 23, IF(F36<=500, 35, IF(F36<=1000, 40, F36*0.04)))), IF(Basic34567891011121314151617181920212223242526272829303132[[#This Row],[نوع الخدمة]]="كاش اوت", IF(F36<=100, 15, IF(F36<=250, 20, IF(F36<=500, 30, IF(F36<=1000, 35, F36*0.035)))), 0))) -> 0 | H36: =IF(I36="مخالفات",50,Basic34567891011121314151617181920212223242526272829303132[[#This Row],[قيمة الرسوم / العموله]]+Basic34567891011121314151617181920212223242526272829303132[[#This Row],[قيمة الشحنه]]) -> 0 | J36: =M$3 -> 1.5.2026 | L36: 25
B37: 34 | G37: =IF(Basic34567891011121314151617181920212223242526272829303132[[#This Row],[نوع الخدمة]]="مخالفات", 50, IF(Basic34567891011121314151617181920212223242526272829303132[[#This Row],[نوع الخدمة]]="كاش ان", IF(F37<=100, 18, IF(F37<=250, 23, IF(F37<=500, 35, IF(F37<=1000, 40, F37*0.04)))), IF(Basic34567891011121314151617181920212223242526272829303132[[#This Row],[نوع الخدمة]]="كاش اوت", IF(F37<=100, 15, IF(F37<=250, 20, IF(F37<=500, 30, IF(F37<=1000, 35, F37*0.035)))), 0))) -> 0 | H37: =IF(I37="مخالفات",50,Basic34567891011121314151617181920212223242526272829303132[[#This Row],[قيمة الرسوم / العموله]]+Basic34567891011121314151617181920212223242526272829303132[[#This Row],[قيمة الشحنه]]) -> 0 | J37: =M$3 -> 1.5.2026 | L37: 26
B38: 35 | G38: =IF(Basic34567891011121314151617181920212223242526272829303132[[#This Row],[نوع الخدمة]]="مخالفات", 50, IF(Basic34567891011121314151617181920212223242526272829303132[[#This Row],[نوع الخدمة]]="كاش ان", IF(F38<=100, 18, IF(F38<=250, 23, IF(F38<=500, 35, IF(F38<=1000, 40, F38*0.04)))), IF(Basic34567891011121314151617181920212223242526272829303132[[#This Row],[نوع الخدمة]]="كاش اوت", IF(F38<=100, 15, IF(F38<=250, 20, IF(F38<=500, 30, IF(F38<=1000, 35, F38*0.035)))), 0))) -> 0 | H38: =IF(I38="مخالفات",50,Basic34567891011121314151617181920212223242526272829303132[[#This Row],[قيمة الرسوم / العموله]]+Basic34567891011121314151617181920212223242526272829303132[[#This Row],[قيمة الشحنه]]) -> 0 | J38: =M$3 -> 1.5.2026 | L38: 27
B39: 36 | G39: =IF(Basic34567891011121314151617181920212223242526272829303132[[#This Row],[نوع الخدمة]]="مخالفات", 50, IF(Basic34567891011121314151617181920212223242526272829303132[[#This Row],[نوع الخدمة]]="كاش ان", IF(F39<=100, 18, IF(F39<=250, 23, IF(F39<=500, 35, IF(F39<=1000, 40, F39*0.04)))), IF(Basic34567891011121314151617181920212223242526272829303132[[#This Row],[نوع الخدمة]]="كاش اوت", IF(F39<=100, 15, IF(F39<=250, 20, IF(F39<=500, 30, IF(F39<=1000, 35, F39*0.035)))), 0))) -> 0 | H39: =IF(I39="مخالفات",50,Basic34567891011121314151617181920212223242526272829303132[[#This Row],[قيمة الرسوم / العموله]]+Basic34567891011121314151617181920212223242526272829303132[[#This Row],[قيمة الشحنه]]) -> 0 | J39: =M$3 -> 1.5.2026 | L39: 28
B40: 37 | G40: =IF(Basic34567891011121314151617181920212223242526272829303132[[#This Row],[نوع الخدمة]]="مخالفات", 50, IF(Basic34567891011121314151617181920212223242526272829303132[[#This Row],[نوع الخدمة]]="كاش ان", IF(F40<=100, 18, IF(F40<=250, 23, IF(F40<=500, 35, IF(F40<=1000, 40, F40*0.04)))), IF(Basic34567891011121314151617181920212223242526272829303132[[#This Row],[نوع الخدمة]]="كاش اوت", IF(F40<=100, 15, IF(F40<=250, 20, IF(F40<=500, 30, IF(F40<=1000, 35, F40*0.035)))), 0))) -> 0 | H40: =IF(I40="مخالفات",50,Basic34567891011121314151617181920212223242526272829303132[[#This Row],[قيمة الرسوم / العموله]]+Basic34567891011121314151617181920212223242526272829303132[[#This Row],[قيمة الشحنه]]) -> 0 | J40: =M$3 -> 1.5.2026 | L40: 29
... B226: 223 | G226: =IF(Basic34567891011121314151617181920212223242526272829303132[[#This Row],[نوع الخدمة]]="مخالفات", 50, IF(Basic34567891011121314151617181920212223242526272829303132[[#This Row],[نوع الخدمة]]="كاش ان", IF(F226<=100, 18, IF(F226<=250, 23, IF(F226<=500, 35, IF(F226<=1000, 40, F226*0.04)))), IF(Basic34567891011121314151617181920212223242526272829303132[[#This Row],[نوع الخدمة]]="كاش اوت", IF(F226<=100, 15, IF(F226<=250, 20, IF(F226<=500, 30, IF(F226<=1000, 35, F226*0.035)))), 0))) -> 0 | H226: =IF(I226="مخالفات",50,Basic34567891011121314151617181920212223242526272829303132[[#This Row],[قيمة الرسوم / العموله]]+Basic34567891011121314151617181920212223242526272829303132[[#This Row],[قيمة الشحنه]]) -> 0 | J226: =M$3 -> 1.5.2026 | L226: 215

Sheet 2
E1: =Total!F5 -> 69 | F1: =Total!G5 -> العبور
B3: م | C3: IPN | D3: إسم العميل | E3: رقم التليفون | F3: قيمة الشحنه | G3: قيمة الرسوم / العموله | H3: الاجمــــــــــالي | I3: نوع الخدمة | J3: التاريخ | L3: التاريخ | M3: 2.5.2026 | O3: مبيعــــــــــــــــــــــــــات الكارت | P3: =M5+M6 -> 0
B4: 1 | C4: 1111111111111 | D4: mohamed | E4: 1066728387 | F4: 1000 | G4: =IF(Basic345678910111213141516171819202122232425262728293031[[#This Row],[نوع الخدمة]]="مخالفات", 50, IF(Basic345678910111213141516171819202122232425262728293031[[#This Row],[نوع الخدمة]]="كاش ان", IF(F4<=100, 18, IF(F4<=250, 23, IF(F4<=500, 35, IF(F4<=1000, 40, F4*0.04)))), IF(Basic345678910111213141516171819202122232425262728293031[[#This Row],[نوع الخدمة]]="كاش اوت", IF(F4<=100, 15, IF(F4<=250, 20, IF(F4<=500, 30, IF(F4<=1000, 35, F4*0.035)))), 0))) -> 35 | H4: =IF(I4="مخالفات",50,Basic345678910111213141516171819202122232425262728293031[[#This Row],[قيمة الرسوم / العموله]]+Basic345678910111213141516171819202122232425262728293031[[#This Row],[قيمة الشحنه]]) -> 1035 | I4: كاش اوت | J4: =M$3 -> 2.5.2026 | L4: العهده | M4: 10000 | O4: رصيد العــــــــــــــــــــــــــــــهده اول اليوم | P4: =M4 -> 10000 | S4: اجمالي الشحنات | T4: اجمالي الكروت
B5: 2 | C5: 1111111111111 | D5: mohamed | E5: 1066728387 | F5: 1000 | G5: =IF(Basic345678910111213141516171819202122232425262728293031[[#This Row],[نوع الخدمة]]="مخالفات", 50, IF(Basic345678910111213141516171819202122232425262728293031[[#This Row],[نوع الخدمة]]="كاش ان", IF(F5<=100, 18, IF(F5<=250, 23, IF(F5<=500, 35, IF(F5<=1000, 40, F5*0.04)))), IF(Basic345678910111213141516171819202122232425262728293031[[#This Row],[نوع الخدمة]]="كاش اوت", IF(F5<=100, 15, IF(F5<=250, 20, IF(F5<=500, 30, IF(F5<=1000, 35, F5*0.035)))), 0))) -> 35 | H5: =IF(I5="مخالفات",50,Basic345678910111213141516171819202122232425262728293031[[#This Row],[قيمة الرسوم / العموله]]+Basic345678910111213141516171819202122232425262728293031[[#This Row],[قيمة الشحنه]]) -> 1035 | I5: كاش اوت | J5: =M$3 -> 2.5.2026 | L5: كارت مصر | O5: مبلغ الشحن (العهده) | P5: =SUMIF(Basic345678910111213141516171819202122232425262728293031[نوع الخدمة],"كاش ان",Basic345678910111213141516171819202122232425262728293031[قيمة الشحنه]) -> 0 | S5: =P5+P9+P12+P7 -> 18645 | T5: =P3 -> 0
B6: 3 | C6: 1111111111111 | D6: mohamed | E6: 1066728387 | F6: 1500 | G6: =IF(Basic345678910111213141516171819202122232425262728293031[[#This Row],[نوع الخدمة]]="مخالفات", 50, IF(Basic345678910111213141516171819202122232425262728293031[[#This Row],[نوع الخدمة]]="كاش ان", IF(F6<=100, 18, IF(F6<=250, 23, IF(F6<=500, 35, IF(F6<=1000, 40, F6*0.04)))), IF(Basic345678910111213141516171819202122232425262728293031[[#This Row],[نوع الخدمة]]="كاش اوت", IF(F6<=100, 15, IF(F6<=250, 20, IF(F6<=500, 30, IF(F6<=1000, 35, F6*0.035)))), 0))) -> 52.5 | H6: =IF(I6="مخالفات",50,Basic345678910111213141516171819202122232425262728293031[[#This Row],[قيمة الرسوم / العموله]]+Basic345678910111213141516171819202122232425262728293031[[#This Row],[قيمة الشحنه]]) -> 1552.5 | I6: كاش اوت | J6: =M$3 -> 2.5.2026 | L6: كارت اهلي | O6: مبلغ الكروت اليومى | P6: =P3*150 -> 0
B7: 4 | C7: 1111111111111 | D7: hesham | E7: 1223911492 | F7: 0 | G7: =IF(Basic345678910111213141516171819202122232425262728293031[[#This Row],[نوع الخدمة]]="مخالفات", 50, IF(Basic345678910111213141516171819202122232425262728293031[[#This Row],[نوع الخدمة]]="كاش ان", IF(F7<=100, 18, IF(F7<=250, 23, IF(F7<=500, 35, IF(F7<=1000, 40, F7*0.04)))), IF(Basic345678910111213141516171819202122232425262728293031[[#This Row],[نوع الخدمة]]="كاش اوت", IF(F7<=100, 15, IF(F7<=250, 20, IF(F7<=500, 30, IF(F7<=1000, 35, F7*0.035)))), 0))) -> 50 | H7: =IF(I7="مخالفات",50,Basic345678910111213141516171819202122232425262728293031[[#This Row],[قيمة الرسوم / العموله]]+Basic345678910111213141516171819202122232425262728293031[[#This Row],[قيمة الشحنه]]) -> 50 | I7: مخالفات | J7: =M$3 -> 2.5.2026 | L7: المردودات | O7: مبلغ المخالفات اليومي | P7: =SUMIF(Basic345678910111213141516171819202122232425262728293031[نوع الخدمة],"مخالفات",Basic345678910111213141516171819202122232425262728293031[الاجمــــــــــالي]) -> 250
B8: 5 | C8: 1111111111111 | D8: essam | E8: 1068799581 | F8: 0 | G8: =IF(Basic345678910111213141516171819202122232425262728293031[[#This Row],[نوع الخدمة]]="مخالفات", 50, IF(Basic345678910111213141516171819202122232425262728293031[[#This Row],[نوع الخدمة]]="كاش ان", IF(F8<=100, 18, IF(F8<=250, 23, IF(F8<=500, 35, IF(F8<=1000, 40, F8*0.04)))), IF(Basic345678910111213141516171819202122232425262728293031[[#This Row],[نوع الخدمة]]="كاش اوت", IF(F8<=100, 15, IF(F8<=250, 20, IF(F8<=500, 30, IF(F8<=1000, 35, F8*0.035)))), 0))) -> 50 | H8: =IF(I8="مخالفات",50,Basic345678910111213141516171819202122232425262728293031[[#This Row],[قيمة الرسوم / العموله]]+Basic345678910111213141516171819202122232425262728293031[[#This Row],[قيمة الشحنه]]) -> 50 | I8: مخالفات | J8: =M$3 -> 2.5.2026 | L8: وارد مصر | M8: 0 | O8: المردودات | P8: =M7 -> 0 | R8: الدايلي تـــــــــــــــــــــــــارجت | S8: تحقيق اليوم | T8: % | U8: الدايلي كروت | V8: تحقيق اليوم | W8: % | BG8: كاش ان
B9: 6 | C9: 1111111111111 | D9: mnoham | E9: 1003681006 | F9: 1000 | G9: =IF(Basic345678910111213141516171819202122232425262728293031[[#This Row],[نوع الخدمة]]="مخالفات", 50, IF(Basic345678910111213141516171819202122232425262728293031[[#This Row],[نوع الخدمة]]="كاش ان", IF(F9<=100, 18, IF(F9<=250, 23, IF(F9<=500, 35, IF(F9<=1000, 40, F9*0.04)))), IF(Basic345678910111213141516171819202122232425262728293031[[#This Row],[نوع الخدمة]]="كاش اوت", IF(F9<=100, 15, IF(F9<=250, 20, IF(F9<=500, 30, IF(F9<=1000, 35, F9*0.035)))), 0))) -> 35 | H9: =IF(I9="مخالفات",50,Basic345678910111213141516171819202122232425262728293031[[#This Row],[قيمة الرسوم / العموله]]+Basic345678910111213141516171819202122232425262728293031[[#This Row],[قيمة الشحنه]]) -> 1035 | I9: كاش اوت | J9: =M$3 -> 2.5.2026 | L9: وارد اهلى | M9: 0 | O9: مبلغ الرسوم | P9: =SUMIF(Basic345678910111213141516171819202122232425262728293031[نوع الخدمة],"كاش ان",Basic345678910111213141516171819202122232425262728293031[قيمة الرسوم / العموله]) -> 0 | R9: =Total!H5/24 -> 29166.667 | S9: =S5 -> 18645 | T9: =S9/R9 -> 0.63925714 | U9: =Total!K5/24 -> 2.9166667 | V9: =T5 -> 0 | W9: =V9/U9 -> 0 | BG9: كاش اوت
B10: 7 | C10: 1111111111111 | D10: mnoham | E10: 1003681006 | F10: 1000 | G10: =IF(Basic345678910111213141516171819202122232425262728293031[[#This Row],[نوع الخدمة]]="مخالفات", 50, IF(Basic345678910111213141516171819202122232425262728293031[[#This Row],[نوع الخدمة]]="كاش ان", IF(F10<=100, 18, IF(F10<=250, 23, IF(F10<=500, 35, IF(F10<=1000, 40, F10*0.04)))), IF(Basic345678910111213141516171819202122232425262728293031[[#This Row],[نوع الخدمة]]="كاش اوت", IF(F10<=100, 15, IF(F10<=250, 20, IF(F10<=500, 30, IF(F10<=1000, 35, F10*0.035)))), 0))) -> 35 | H10: =IF(I10="مخالفات",50,Basic345678910111213141516171819202122232425262728293031[[#This Row],[قيمة الرسوم / العموله]]+Basic345678910111213141516171819202122232425262728293031[[#This Row],[قيمة الشحنه]]) -> 1035 | I10: كاش اوت | J10: =M$3 -> 2.5.2026 | O10: اجمالي كاش اوت(بدون الرسوم) | P10: =SUMIF(Basic345678910111213141516171819202122232425262728293031[نوع الخدمة],"كاش اوت",Basic345678910111213141516171819202122232425262728293031[قيمة الشحنه]) -> 17700 | R10: =(W9+T9)/2 -> 0.31962857 | BG10: مخالفات
B11: 8 | C11: 1111111111111 | D11: mnoham | E11: 1003681006 | F11: 500 | G11: =IF(Basic345678910111213141516171819202122232425262728293031[[#This Row],[نوع الخدمة]]="مخالفات", 50, IF(Basic345678910111213141516171819202122232425262728293031[[#This Row],[نوع الخدمة]]="كاش ان", IF(F11<=100, 18, IF(F11<=250, 23, IF(F11<=500, 35, IF(F11<=1000, 40, F11*0.04)))), IF(Basic345678910111213141516171819202122232425262728293031[[#This Row],[نوع الخدمة]]="كاش اوت", IF(F11<=100, 15, IF(F11<=250, 20, IF(F11<=500, 30, IF(F11<=1000, 35, F11*0.035)))), 0))) -> 30 | H11: =IF(I11="مخالفات",50,Basic345678910111213141516171819202122232425262728293031[[#This Row],[قيمة الرسوم / العموله]]+Basic345678910111213141516171819202122232425262728293031[[#This Row],[قيمة الشحنه]]) -> 530 | I11: كاش اوت | J11: =M$3 -> 2.5.2026 | L11: # | M11: التوكن | O11: التوريـــــــــــــــــــــــــــــــــــــــــد النقدي( الدرج) | P11: =(P5+P6+P9+P7+P4)-P10-P8 -> -7450
B12: 9 | C12: 1111111111111 | D12: mnoham | E12: 1003681006 | F12: 1500 | G12: =IF(Basic345678910111213141516171819202122232425262728293031[[#This Row],[نوع الخدمة]]="مخالفات", 50, IF(Basic345678910111213141516171819202122232425262728293031[[#This Row],[نوع الخدمة]]="كاش ان", IF(F12<=100, 18, IF(F12<=250, 23, IF(F12<=500, 35, IF(F12<=1000, 40, F12*0.04)))), IF(Basic345678910111213141516171819202122232425262728293031[[#This Row],[نوع الخدمة]]="كاش اوت", IF(F12<=100, 15, IF(F12<=250, 20, IF(F12<=500, 30, IF(F12<=1000, 35, F12*0.035)))), 0))) -> 52.5 | H12: =IF(I12="مخالفات",50,Basic345678910111213141516171819202122232425262728293031[[#This Row],[قيمة الرسوم / العموله]]+Basic345678910111213141516171819202122232425262728293031[[#This Row],[قيمة الشحنه]]) -> 1552.5 | I12: كاش اوت | J12: =M$3 -> 2.5.2026 | L12: 1 | O12: اجمالي كاش اوت( بالرسوم) | P12: =SUMIF(Basic345678910111213141516171819202122232425262728293031[نوع الخدمة],"كاش اوت",Basic345678910111213141516171819202122232425262728293031[الاجمــــــــــالي]) -> 18395
B13: 10 | C13: 1111111111111 | D13: mnoham | E13: 1003681006 | F13: 1500 | G13: =IF(Basic345678910111213141516171819202122232425262728293031[[#This Row],[نوع الخدمة]]="مخالفات", 50, IF(Basic345678910111213141516171819202122232425262728293031[[#This Row],[نوع الخدمة]]="كاش ان", IF(F13<=100, 18, IF(F13<=250, 23, IF(F13<=500, 35, IF(F13<=1000, 40, F13*0.04)))), IF(Basic345678910111213141516171819202122232425262728293031[[#This Row],[نوع الخدمة]]="كاش اوت", IF(F13<=100, 15, IF(F13<=250, 20, IF(F13<=500, 30, IF(F13<=1000, 35, F13*0.035)))), 0))) -> 52.5 | H13: =IF(I13="مخالفات",50,Basic345678910111213141516171819202122232425262728293031[[#This Row],[قيمة الرسوم / العموله]]+Basic345678910111213141516171819202122232425262728293031[[#This Row],[قيمة الشحنه]]) -> 1552.5 | I13: كاش اوت | J13: =M$3 -> 2.5.2026 | L13: 2
B14: 11 | C14: 1111111111111 | D14: mnoham | E14: 1003681006 | F14: 200 | G14: =IF(Basic345678910111213141516171819202122232425262728293031[[#This Row],[نوع الخدمة]]="مخالفات", 50, IF(Basic345678910111213141516171819202122232425262728293031[[#This Row],[نوع الخدمة]]="كاش ان", IF(F14<=100, 18, IF(F14<=250, 23, IF(F14<=500, 35, IF(F14<=1000, 40, F14*0.04)))), IF(Basic345678910111213141516171819202122232425262728293031[[#This Row],[نوع الخدمة]]="كاش اوت", IF(F14<=100, 15, IF(F14<=250, 20, IF(F14<=500, 30, IF(F14<=1000, 35, F14*0.035)))), 0))) -> 20 | H14: =IF(I14="مخالفات",50,Basic345678910111213141516171819202122232425262728293031[[#This Row],[قيمة الرسوم / العموله]]+Basic345678910111213141516171819202122232425262728293031[[#This Row],[قيمة الشحنه]]) -> 220 | I14: كاش اوت | J14: =M$3 -> 2.5.2026 | L14: 3
B15: 12 | C15: 1111111111111 | D15: Mohamed | E15: 100368106 | F15: 500 | G15: =IF(Basic345678910111213141516171819202122232425262728293031[[#This Row],[نوع الخدمة]]="مخالفات", 50, IF(Basic345678910111213141516171819202122232425262728293031[[#This Row],[نوع الخدمة]]="كاش ان", IF(F15<=100, 18, IF(F15<=250, 23, IF(F15<=500, 35, IF(F15<=1000, 40, F15*0.04)))), IF(Basic345678910111213141516171819202122232425262728293031[[#This Row],[نوع الخدمة]]="كاش اوت", IF(F15<=100, 15, IF(F15<=250, 20, IF(F15<=500, 30, IF(F15<=1000, 35, F15*0.035)))), 0))) -> 30 | H15: =IF(I15="مخالفات",50,Basic345678910111213141516171819202122232425262728293031[[#This Row],[قيمة الرسوم / العموله]]+Basic345678910111213141516171819202122232425262728293031[[#This Row],[قيمة الشحنه]]) -> 530 | I15: كاش اوت | J15: =M$3 -> 2.5.2026 | L15: 4 | O15: مخالفات | P15: =COUNTIF(Basic345678910111213141516171819202122232425262728293031[نوع الخدمة],"مخالفات") -> 5
B16: 13 | C16: 1111111111111 | D16: hind | E16: 111251245 | F16: 0 | G16: =IF(Basic345678910111213141516171819202122232425262728293031[[#This Row],[نوع الخدمة]]="مخالفات", 50, IF(Basic345678910111213141516171819202122232425262728293031[[#This Row],[نوع الخدمة]]="كاش ان", IF(F16<=100, 18, IF(F16<=250, 23, IF(F16<=500, 35, IF(F16<=1000, 40, F16*0.04)))), IF(Basic345678910111213141516171819202122232425262728293031[[#This Row],[نوع الخدمة]]="كاش اوت", IF(F16<=100, 15, IF(F16<=250, 20, IF(F16<=500, 30, IF(F16<=1000, 35, F16*0.035)))), 0))) -> 50 | H16: =IF(I16="مخالفات",50,Basic345678910111213141516171819202122232425262728293031[[#This Row],[قيمة الرسوم / العموله]]+Basic345678910111213141516171819202122232425262728293031[[#This Row],[قيمة الشحنه]]) -> 50 | I16: مخالفات | J16: =M$3 -> 2.5.2026 | L16: 5 | O16: عدد الحركات Cash In | P16: =COUNTIF(Basic345678910111213141516171819202122232425262728293031[نوع الخدمة],"كاش ان") -> 0
B17: 14 | C17: 1111111111111 | D17: Mohamed | E17: 1003681006 | F17: 500 | G17: =IF(Basic345678910111213141516171819202122232425262728293031[[#This Row],[نوع الخدمة]]="مخالفات", 50, IF(Basic345678910111213141516171819202122232425262728293031[[#This Row],[نوع الخدمة]]="كاش ان", IF(F17<=100, 18, IF(F17<=250, 23, IF(F17<=500, 35, IF(F17<=1000, 40, F17*0.04)))), IF(Basic345678910111213141516171819202122232425262728293031[[#This Row],[نوع الخدمة]]="كاش اوت", IF(F17<=100, 15, IF(F17<=250, 20, IF(F17<=500, 30, IF(F17<=1000, 35, F17*0.035)))), 0))) -> 30 | H17: =IF(I17="مخالفات",50,Basic345678910111213141516171819202122232425262728293031[[#This Row],[قيمة الرسوم / العموله]]+Basic345678910111213141516171819202122232425262728293031[[#This Row],[قيمة الشحنه]]) -> 530 | I17: كاش اوت | J17: =M$3 -> 2.5.2026 | L17: 6 | O17: عدد الحركات Cash Out | P17: =COUNTIF(Basic345678910111213141516171819202122232425262728293031[نوع الخدمة],"كاش اوت") -> 19
B18: 15 | C18: 1111111111111 | D18: Mohamed | E18: 1003681006 | F18: 500 | G18: =IF(Basic345678910111213141516171819202122232425262728293031[[#This Row],[نوع الخدمة]]="مخالفات", 50, IF(Basic345678910111213141516171819202122232425262728293031[[#This Row],[نوع الخدمة]]="كاش ان", IF(F18<=100, 18, IF(F18<=250, 23, IF(F18<=500, 35, IF(F18<=1000, 40, F18*0.04)))), IF(Basic345678910111213141516171819202122232425262728293031[[#This Row],[نوع الخدمة]]="كاش اوت", IF(F18<=100, 15, IF(F18<=250, 20, IF(F18<=500, 30, IF(F18<=1000, 35, F18*0.035)))), 0))) -> 30 | H18: =IF(I18="مخالفات",50,Basic345678910111213141516171819202122232425262728293031[[#This Row],[قيمة الرسوم / العموله]]+Basic345678910111213141516171819202122232425262728293031[[#This Row],[قيمة الشحنه]]) -> 530 | I18: كاش اوت | J18: =M$3 -> 2.5.2026 | L18: 7 | O18: اجمالى عدد الحركات | P18: =P16+P17 -> 19
B19: 16 | C19: 1111111111111 | D19: omar | E19: 1055005194 | F19: 0 | G19: =IF(Basic345678910111213141516171819202122232425262728293031[[#This Row],[نوع الخدمة]]="مخالفات", 50, IF(Basic345678910111213141516171819202122232425262728293031[[#This Row],[نوع الخدمة]]="كاش ان", IF(F19<=100, 18, IF(F19<=250, 23, IF(F19<=500, 35, IF(F19<=1000, 40, F19*0.04)))), IF(Basic345678910111213141516171819202122232425262728293031[[#This Row],[نوع الخدمة]]="كاش اوت", IF(F19<=100, 15, IF(F19<=250, 20, IF(F19<=500, 30, IF(F19<=1000, 35, F19*0.035)))), 0))) -> 50 | H19: =IF(I19="مخالفات",50,Basic345678910111213141516171819202122232425262728293031[[#This Row],[قيمة الرسوم / العموله]]+Basic345678910111213141516171819202122232425262728293031[[#This Row],[قيمة الشحنه]]) -> 50 | I19: مخالفات | J19: =M$3 -> 2.5.2026 | L19: 8
B20: 17 | C20: 1111111111111 | D20: Mohamed | E20: 1003681006 | F20: 1000 | G20: =IF(Basic345678910111213141516171819202122232425262728293031[[#This Row],[نوع الخدمة]]="مخالفات", 50, IF(Basic345678910111213141516171819202122232425262728293031[[#This Row],[نوع الخدمة]]="كاش ان", IF(F20<=100, 18, IF(F20<=250, 23, IF(F20<=500, 35, IF(F20<=1000, 40, F20*0.04)))), IF(Basic345678910111213141516171819202122232425262728293031[[#This Row],[نوع الخدمة]]="كاش اوت", IF(F20<=100, 15, IF(F20<=250, 20, IF(F20<=500, 30, IF(F20<=1000, 35, F20*0.035)))), 0))) -> 35 | H20: =IF(I20="مخالفات",50,Basic345678910111213141516171819202122232425262728293031[[#This Row],[قيمة الرسوم / العموله]]+Basic345678910111213141516171819202122232425262728293031[[#This Row],[قيمة الشحنه]]) -> 1035 | I20: كاش اوت | J20: =M$3 -> 2.5.2026 | L20: 9 | O20: الجــــــــــــرد الفعلي للكروت
B21: 18 | C21: 1111111111111 | D21: Mohamed | E21: 1003681006 | F21: 1500 | G21: =IF(Basic345678910111213141516171819202122232425262728293031[[#This Row],[نوع الخدمة]]="مخالفات", 50, IF(Basic345678910111213141516171819202122232425262728293031[[#This Row],[نوع الخدمة]]="كاش ان", IF(F21<=100, 18, IF(F21<=250, 23, IF(F21<=500, 35, IF(F21<=1000, 40, F21*0.04)))), IF(Basic345678910111213141516171819202122232425262728293031[[#This Row],[نوع الخدمة]]="كاش اوت", IF(F21<=100, 15, IF(F21<=250, 20, IF(F21<=500, 30, IF(F21<=1000, 35, F21*0.035)))), 0))) -> 52.5 | H21: =IF(I21="مخالفات",50,Basic345678910111213141516171819202122232425262728293031[[#This Row],[قيمة الرسوم / العموله]]+Basic345678910111213141516171819202122232425262728293031[[#This Row],[قيمة الشحنه]]) -> 1552.5 | I21: كاش اوت | J21: =M$3 -> 2.5.2026 | L21: 10 | O21: المخـــــــــــــــــــــــــــــــــــــــــزون
B22: 19 | C22: 1111111111111 | D22: Mohamed | E22: 1003681006 | F22: 500 | G22: =IF(Basic345678910111213141516171819202122232425262728293031[[#This Row],[نوع الخدمة]]="مخالفات", 50, IF(Basic345678910111213141516171819202122232425262728293031[[#This Row],[نوع الخدمة]]="كاش ان", IF(F22<=100, 18, IF(F22<=250, 23, IF(F22<=500, 35, IF(F22<=1000, 40, F22*0.04)))), IF(Basic345678910111213141516171819202122232425262728293031[[#This Row],[نوع الخدمة]]="كاش اوت", IF(F22<=100, 15, IF(F22<=250, 20, IF(F22<=500, 30, IF(F22<=1000, 35, F22*0.035)))), 0))) -> 30 | H22: =IF(I22="مخالفات",50,Basic345678910111213141516171819202122232425262728293031[[#This Row],[قيمة الرسوم / العموله]]+Basic345678910111213141516171819202122232425262728293031[[#This Row],[قيمة الشحنه]]) -> 530 | I22: كاش اوت | J22: =M$3 -> 2.5.2026 | L22: 11 | O22: كارت مصر | P22: =M8+'1 '!P27 -> 0
B23: 20 | C23: 1111111111111 | D23: Mohamed | E23: 1003681006 | F23: 1000 | G23: =IF(Basic345678910111213141516171819202122232425262728293031[[#This Row],[نوع الخدمة]]="مخالفات", 50, IF(Basic345678910111213141516171819202122232425262728293031[[#This Row],[نوع الخدمة]]="كاش ان", IF(F23<=100, 18, IF(F23<=250, 23, IF(F23<=500, 35, IF(F23<=1000, 40, F23*0.04)))), IF(Basic345678910111213141516171819202122232425262728293031[[#This Row],[نوع الخدمة]]="كاش اوت", IF(F23<=100, 15, IF(F23<=250, 20, IF(F23<=500, 30, IF(F23<=1000, 35, F23*0.035)))), 0))) -> 35 | H23: =IF(I23="مخالفات",50,Basic345678910111213141516171819202122232425262728293031[[#This Row],[قيمة الرسوم / العموله]]+Basic345678910111213141516171819202122232425262728293031[[#This Row],[قيمة الشحنه]]) -> 1035 | I23: كاش اوت | J23: =M$3 -> 2.5.2026 | L23: 12 | O23: كارت اهلي | P23: =M9+'1 '!P28 -> 0
B24: 21 | C24: 1111111111111 | D24: Mohamed | E24: 1003681006 | F24: 1000 | G24: =IF(Basic345678910111213141516171819202122232425262728293031[[#This Row],[نوع الخدمة]]="مخالفات", 50, IF(Basic345678910111213141516171819202122232425262728293031[[#This Row],[نوع الخدمة]]="كاش ان", IF(F24<=100, 18, IF(F24<=250, 23, IF(F24<=500, 35, IF(F24<=1000, 40, F24*0.04)))), IF(Basic345678910111213141516171819202122232425262728293031[[#This Row],[نوع الخدمة]]="كاش اوت", IF(F24<=100, 15, IF(F24<=250, 20, IF(F24<=500, 30, IF(F24<=1000, 35, F24*0.035)))), 0))) -> 35 | H24: =IF(I24="مخالفات",50,Basic345678910111213141516171819202122232425262728293031[[#This Row],[قيمة الرسوم / العموله]]+Basic345678910111213141516171819202122232425262728293031[[#This Row],[قيمة الشحنه]]) -> 1035 | I24: كاش اوت | J24: =M$3 -> 2.5.2026 | L24: 13 | O24: المبيــــــــــــــــــــــــــــــــــــــــــــــــعات
B25: 22 | C25: 1111111111111 | D25: Mohamed | E25: 1003681006 | F25: 1000 | G25: =IF(Basic345678910111213141516171819202122232425262728293031[[#This Row],[نوع الخدمة]]="مخالفات", 50, IF(Basic345678910111213141516171819202122232425262728293031[[#This Row],[نوع الخدمة]]="كاش ان", IF(F25<=100, 18, IF(F25<=250, 23, IF(F25<=500, 35, IF(F25<=1000, 40, F25*0.04)))), IF(Basic345678910111213141516171819202122232425262728293031[[#This Row],[نوع الخدمة]]="كاش اوت", IF(F25<=100, 15, IF(F25<=250, 20, IF(F25<=500, 30, IF(F25<=1000, 35, F25*0.035)))), 0))) -> 35 | H25: =IF(I25="مخالفات",50,Basic345678910111213141516171819202122232425262728293031[[#This Row],[قيمة الرسوم / العموله]]+Basic345678910111213141516171819202122232425262728293031[[#This Row],[قيمة الشحنه]]) -> 1035 | I25: كاش اوت | J25: =M$3 -> 2.5.2026 | L25: 14 | O25: كارت مصر | P25: =M5 -> 0
B26: 23 | C26: 1111111111111 | D26: Mohamed | E26: 1003681006 | F26: 1000 | G26: =IF(Basic345678910111213141516171819202122232425262728293031[[#This Row],[نوع الخدمة]]="مخالفات", 50, IF(Basic345678910111213141516171819202122232425262728293031[[#This Row],[نوع الخدمة]]="كاش ان", IF(F26<=100, 18, IF(F26<=250, 23, IF(F26<=500, 35, IF(F26<=1000, 40, F26*0.04)))), IF(Basic345678910111213141516171819202122232425262728293031[[#This Row],[نوع الخدمة]]="كاش اوت", IF(F26<=100, 15, IF(F26<=250, 20, IF(F26<=500, 30, IF(F26<=1000, 35, F26*0.035)))), 0))) -> 35 | H26: =IF(I26="مخالفات",50,Basic345678910111213141516171819202122232425262728293031[[#This Row],[قيمة الرسوم / العموله]]+Basic345678910111213141516171819202122232425262728293031[[#This Row],[قيمة الشحنه]]) -> 1035 | I26: كاش اوت | J26: =M$3 -> 2.5.2026 | L26: 15 | O26: كارت اهلي | P26: =M6 -> 0
B27: 24 | C27: 1111111111111 | D27: abdullah | E27: 01003681006 | F27: 0 | G27: =IF(Basic345678910111213141516171819202122232425262728293031[[#This Row],[نوع الخدمة]]="مخالفات", 50, IF(Basic345678910111213141516171819202122232425262728293031[[#This Row],[نوع الخدمة]]="كاش ان", IF(F27<=100, 18, IF(F27<=250, 23, IF(F27<=500, 35, IF(F27<=1000, 40, F27*0.04)))), IF(Basic345678910111213141516171819202122232425262728293031[[#This Row],[نوع الخدمة]]="كاش اوت", IF(F27<=100, 15, IF(F27<=250, 20, IF(F27<=500, 30, IF(F27<=1000, 35, F27*0.035)))), 0))) -> 50 | H27: =IF(I27="مخالفات",50,Basic345678910111213141516171819202122232425262728293031[[#This Row],[قيمة الرسوم / العموله]]+Basic345678910111213141516171819202122232425262728293031[[#This Row],[قيمة الشحنه]]) -> 50 | I27: مخالفات | J27: =M$3 -> 2.5.2026 | L27: 16 | O27: المتبــــــــــــــــــــــــــــــــــــــــــــــــــــــقي
B28: 25 | G28: =IF(Basic345678910111213141516171819202122232425262728293031[[#This Row],[نوع الخدمة]]="مخالفات", 50, IF(Basic345678910111213141516171819202122232425262728293031[[#This Row],[نوع الخدمة]]="كاش ان", IF(F28<=100, 18, IF(F28<=250, 23, IF(F28<=500, 35, IF(F28<=1000, 40, F28*0.04)))), IF(Basic345678910111213141516171819202122232425262728293031[[#This Row],[نوع الخدمة]]="كاش اوت", IF(F28<=100, 15, IF(F28<=250, 20, IF(F28<=500, 30, IF(F28<=1000, 35, F28*0.035)))), 0))) -> 0 | H28: =IF(I28="مخالفات",50,Basic345678910111213141516171819202122232425262728293031[[#This Row],[قيمة الرسوم / العموله]]+Basic345678910111213141516171819202122232425262728293031[[#This Row],[قيمة الشحنه]]) -> 0 | J28: =M$3 -> 2.5.2026 | L28: 17 | O28: كارت مصر | P28: =P22-P25 -> 0
B29: 26 | G29: =IF(Basic345678910111213141516171819202122232425262728293031[[#This Row],[نوع الخدمة]]="مخالفات", 50, IF(Basic345678910111213141516171819202122232425262728293031[[#This Row],[نوع الخدمة]]="كاش ان", IF(F29<=100, 18, IF(F29<=250, 23, IF(F29<=500, 35, IF(F29<=1000, 40, F29*0.04)))), IF(Basic345678910111213141516171819202122232425262728293031[[#This Row],[نوع الخدمة]]="كاش اوت", IF(F29<=100, 15, IF(F29<=250, 20, IF(F29<=500, 30, IF(F29<=1000, 35, F29*0.035)))), 0))) -> 0 | H29: =IF(I29="مخالفات",50,Basic345678910111213141516171819202122232425262728293031[[#This Row],[قيمة الرسوم / العموله]]+Basic345678910111213141516171819202122232425262728293031[[#This Row],[قيمة الشحنه]]) -> 0 | J29: =M$3 -> 2.5.2026 | L29: 18 | O29: كارت اهلي | P29: =P23-P26 -> 0
B30: 27 | G30: =IF(Basic345678910111213141516171819202122232425262728293031[[#This Row],[نوع الخدمة]]="مخالفات", 50, IF(Basic345678910111213141516171819202122232425262728293031[[#This Row],[نوع الخدمة]]="كاش ان", IF(F30<=100, 18, IF(F30<=250, 23, IF(F30<=500, 35, IF(F30<=1000, 40, F30*0.04)))), IF(Basic345678910111213141516171819202122232425262728293031[[#This Row],[نوع الخدمة]]="كاش اوت", IF(F30<=100, 15, IF(F30<=250, 20, IF(F30<=500, 30, IF(F30<=1000, 35, F30*0.035)))), 0))) -> 0 | H30: =IF(I30="مخالفات",50,Basic345678910111213141516171819202122232425262728293031[[#This Row],[قيمة الرسوم / العموله]]+Basic345678910111213141516171819202122232425262728293031[[#This Row],[قيمة الشحنه]]) -> 0 | J30: =M$3 -> 2.5.2026 | L30: 19
B31: 28 | G31: =IF(Basic345678910111213141516171819202122232425262728293031[[#This Row],[نوع الخدمة]]="مخالفات", 50, IF(Basic345678910111213141516171819202122232425262728293031[[#This Row],[نوع الخدمة]]="كاش ان", IF(F31<=100, 18, IF(F31<=250, 23, IF(F31<=500, 35, IF(F31<=1000, 40, F31*0.04)))), IF(Basic345678910111213141516171819202122232425262728293031[[#This Row],[نوع الخدمة]]="كاش اوت", IF(F31<=100, 15, IF(F31<=250, 20, IF(F31<=500, 30, IF(F31<=1000, 35, F31*0.035)))), 0))) -> 0 | H31: =IF(I31="مخالفات",50,Basic345678910111213141516171819202122232425262728293031[[#This Row],[قيمة الرسوم / العموله]]+Basic345678910111213141516171819202122232425262728293031[[#This Row],[قيمة الشحنه]]) -> 0 | J31: =M$3 -> 2.5.2026 | L31: 20
B32: 29 | G32: =IF(Basic345678910111213141516171819202122232425262728293031[[#This Row],[نوع الخدمة]]="مخالفات", 50, IF(Basic345678910111213141516171819202122232425262728293031[[#This Row],[نوع الخدمة]]="كاش ان", IF(F32<=100, 18, IF(F32<=250, 23, IF(F32<=500, 35, IF(F32<=1000, 40, F32*0.04)))), IF(Basic345678910111213141516171819202122232425262728293031[[#This Row],[نوع الخدمة]]="كاش اوت", IF(F32<=100, 15, IF(F32<=250, 20, IF(F32<=500, 30, IF(F32<=1000, 35, F32*0.035)))), 0))) -> 0 | H32: =IF(I32="مخالفات",50,Basic345678910111213141516171819202122232425262728293031[[#This Row],[قيمة الرسوم / العموله]]+Basic345678910111213141516171819202122232425262728293031[[#This Row],[قيمة الشحنه]]) -> 0 | J32: =M$3 -> 2.5.2026 | L32: 21
B33: 30 | G33: =IF(Basic345678910111213141516171819202122232425262728293031[[#This Row],[نوع الخدمة]]="مخالفات", 50, IF(Basic345678910111213141516171819202122232425262728293031[[#This Row],[نوع الخدمة]]="كاش ان", IF(F33<=100, 18, IF(F33<=250, 23, IF(F33<=500, 35, IF(F33<=1000, 40, F33*0.04)))), IF(Basic345678910111213141516171819202122232425262728293031[[#This Row],[نوع الخدمة]]="كاش اوت", IF(F33<=100, 15, IF(F33<=250, 20, IF(F33<=500, 30, IF(F33<=1000, 35, F33*0.035)))), 0))) -> 0 | H33: =IF(I33="مخالفات",50,Basic345678910111213141516171819202122232425262728293031[[#This Row],[قيمة الرسوم / العموله]]+Basic345678910111213141516171819202122232425262728293031[[#This Row],[قيمة الشحنه]]) -> 0 | J33: =M$3 -> 2.5.2026 | L33: 22
B34: 31 | G34: =IF(Basic345678910111213141516171819202122232425262728293031[[#This Row],[نوع الخدمة]]="مخالفات", 50, IF(Basic345678910111213141516171819202122232425262728293031[[#This Row],[نوع الخدمة]]="كاش ان", IF(F34<=100, 18, IF(F34<=250, 23, IF(F34<=500, 35, IF(F34<=1000, 40, F34*0.04)))), IF(Basic345678910111213141516171819202122232425262728293031[[#This Row],[نوع الخدمة]]="كاش اوت", IF(F34<=100, 15, IF(F34<=250, 20, IF(F34<=500, 30, IF(F34<=1000, 35, F34*0.035)))), 0))) -> 0 | H34: =IF(I34="مخالفات",50,Basic345678910111213141516171819202122232425262728293031[[#This Row],[قيمة الرسوم / العموله]]+Basic345678910111213141516171819202122232425262728293031[[#This Row],[قيمة الشحنه]]) -> 0 | J34: =M$3 -> 2.5.2026 | L34: 23
B35: 32 | G35: =IF(Basic345678910111213141516171819202122232425262728293031[[#This Row],[نوع الخدمة]]="مخالفات", 50, IF(Basic345678910111213141516171819202122232425262728293031[[#This Row],[نوع الخدمة]]="كاش ان", IF(F35<=100, 18, IF(F35<=250, 23, IF(F35<=500, 35, IF(F35<=1000, 40, F35*0.04)))), IF(Basic345678910111213141516171819202122232425262728293031[[#This Row],[نوع الخدمة]]="كاش اوت", IF(F35<=100, 15, IF(F35<=250, 20, IF(F35<=500, 30, IF(F35<=1000, 35, F35*0.035)))), 0))) -> 0 | H35: =IF(I35="مخالفات",50,Basic345678910111213141516171819202122232425262728293031[[#This Row],[قيمة الرسوم / العموله]]+Basic345678910111213141516171819202122232425262728293031[[#This Row],[قيمة الشحنه]]) -> 0 | J35: =M$3 -> 2.5.2026 | L35: 24
